<?xml version="1.0"?>
<robot name="physics">

	<link name="body1">
		<visual>
			<geometry>
				<box size="1 1 1"/>
			</geometry>
			<origin rpy="0 0 0" xyz="0 0 0"/>
			<material name="white">
				<color rgba="1 1 1 1"/>
			</material>
		</visual>
		<collision>
			<geometry>
				<box size="1 1 1"/>
			</geometry>
			<origin rpy="0 0 0" xyz="0 0 0"/>
		</collision>
		<inertial>
			<mass value="0"/>
			<origin rpy="0 0 0" xyz="0 0 0 "/>
			<inertia ixx="1.0" ixy="0.0" ixz="0.0" iyy="1.0" iyz="0.0" izz="1.0"/>
		</inertial>
	</link>

	<link name="body2">
		<visual>
			<geometry>
				<box size="1 1 1"/>
			</geometry>
			<origin rpy="0 0 0" xyz="3 0 0"/>
			<material name="red">
				<color rgba="0.8 0 0 1"/>
			</material>
		</visual>
		<collision>
			<geometry>
				<box size="1 1 1"/>
			</geometry>
			<origin rpy="0 0 0" xyz="3 0 0"/>
		</collision>
		<inertial>
			<mass value="1"/>
			<origin rpy="0 0 0" xyz="0 0 0"/>
			<inertia ixx="1.0" ixy="0.0" ixz="0.0" iyy="1.0" iyz="0.0" izz="1.0"/>
		</inertial>
	</link>

	<link name="body3">
		<visual>
			<geometry>
				<box size="1 1 1"/>
			</geometry>
			<origin rpy="0 0 0" xyz="0 0 3"/>
			<material name="green">
				<color rgba="0 0.8 0 1"/>
			</material>
		</visual>
		<collision>
			<geometry>
				<box size="1 1 1"/>
			</geometry>
			<origin rpy="0 0 0" xyz="0 0 3"/>
		</collision>
		<inertial>
			<mass value="1"/>
			<origin rpy="0 0 0" xyz="0 0 0"/>
			<inertia ixx="1.0" ixy="0.0" ixz="0.0" iyy="1.0" iyz="0.0" izz="1.0"/>
		</inertial>
	</link>

	<link name="body4">
		<visual>
			<geometry>
				<box size="1 1 1"/>
			</geometry>
			<origin rpy="0 0 0" xyz="-3 0 0"/>
			<material name="blue">
				<color rgba="0 0 0.8 1"/>
			</material>
		</visual>
		<collision>
			<geometry>
				<box size="1 1 1"/>
			</geometry>
			<origin rpy="0 0 0" xyz="-3 0 0"/>
		</collision>
		<inertial>
			<mass value="1"/>
			<origin rpy="0 0 0" xyz="0 0 0"/>
			<inertia ixx="1.0" ixy="0.0" ixz="0.0" iyy="1.0" iyz="0.0" izz="1.0"/>
		</inertial>
	</link>

	<link name="body5">
		<visual>
			<geometry>
				<box size="1 1 1"/>
			</geometry>
			<origin rpy="0 0 0" xyz="0 0 0"/>
			<material name="green">
				<color rgba="0 0.8 0 1"/>
			</material>
		</visual>
		<collision>
			<geometry>
				<box size="1 1 1"/>
			</geometry>
			<origin rpy="0 0 0" xyz="0 0 0"/>
		</collision>
		<inertial>
			<mass value="1"/>
			<origin rpy="0 0 0" xyz="0 0 0"/>
			<inertia ixx="1.0" ixy="0.0" ixz="0.0" iyy="1.0" iyz="0.0" izz="1.0"/>
		</inertial>
	</link>

	<!-- <joint name="Slider" type="prismatic">
		<axis xyz="1 0 0"/>
		<limit effort="1000.0" lower="-2" upper="2" velocity="0.5"/>
		<origin rpy="0 0 0" xyz="0 0.0 0.0"/>
		<parent link="body1"/>
		<child link="body2"/>
	</joint> -->

	<joint name="Hinge1" type="revolute">
		<axis xyz="0 1 0"/>
		<limit effort="1000.0" lower="1" upper="-1" velocity="0.5"/>
		<origin rpy="0 0 0" xyz="0 0 0"/>
		<parent link="body1"/>
		<child link="body2"/>
	</joint>

	<joint name="Hinge2" type="revolute">
		<axis xyz="0 1 0"/>
		<limit effort="1000.0" lower="1" upper="-1" velocity="0.5"/>
		<origin rpy="0 0 0" xyz="3 0 0"/>
		<parent link="body2"/>
		<child link="body3"/>
	</joint>

	<joint name="Hinge3" type="revolute">
		<axis xyz="0 1 0"/>
		<limit effort="1000.0" lower="1" upper="-1" velocity="0.5"/>
		<origin rpy="0 0 0" xyz="0 0 3"/>
		<parent link="body3"/>
		<child link="body4"/>
	</joint>

	<joint name="Hinge4" type="revolute">
		<axis xyz="0 1 0"/>
		<limit effort="1000.0" lower="1" upper="-1" velocity="0.5"/>
		<origin rpy="0 0 0" xyz="-3 0 0"/>
		<parent link="body4"/>
		<child link="body5"/>
	</joint>

</robot>