<?xml version="1.0"?>
<robot name="robot2">

	<link name="body1">
		<visual>
			<geometry>
				<box size="1 1 1"/>
			</geometry>
			<origin rpy="0 0 0" xyz="2 0 0"/>
			<material name="red">
				<color rgba="0.8 0 0 1"/>
			</material>
		</visual>
		<collision>
			<geometry>
				<box size="1 1 1"/>
			</geometry>
			<origin rpy="0 0 0" xyz="2 0 0"/>
		</collision>
		<inertial>
			<mass value="1"/>
			<origin rpy="0 0 0" xyz="0 0 0 "/>
			<inertia ixx="1.0" ixy="0.0" ixz="0.0" iyy="1.0" iyz="0.0" izz="1.0"/>
		</inertial>
	</link>

	<link name="body2">
		<visual>
			<geometry>
				<box size="1 1 1"/>
			</geometry>
			<origin rpy="0 0 0" xyz="2 0 0"/>
			<material name="red">
				<color rgba="0.8 0 0 1"/>
			</material>
		</visual>
		<collision>
			<geometry>
				<box size="1 1 1"/>
			</geometry>
			<origin rpy="0 0 0" xyz="2 0 0"/>
		</collision>
		<inertial>
			<mass value="1"/>
			<origin rpy="0 0 0" xyz="0 0 0 "/>
			<inertia ixx="1.0" ixy="0.0" ixz="0.0" iyy="1.0" iyz="0.0" izz="1.0"/>
		</inertial>
	</link>

	<joint name="Hinge1" type="revolute">
		<axis xyz="0 1 0"/>
		<limit effort="1000.0" lower="1" upper="-1" velocity="0.5"/>
		<origin rpy="0 0 0" xyz="2 0 0"/>
		<parent link="body1"/>
		<child link="body2"/>
	</joint>
</robot>